Workbook

Sheet Data
A1: Store | B1: Date | C1: Product | D1: Weekly_Sales | E1: inventory level | F1: Temperature | G1: Past promotion of product in lac | H1: demand forecast
A2: 1 | B2: 40214 | C2: Blueberry scented candle | D2: 1643690.9 | E2: 64552 | F2: 42.31 | G2: 2572 | H2: 8106
A3: 4 | B3: 40221 | C3: Stainless steel water bottle | D3: 1641957.4 | E3: 33106 | F3: 38.51 | G3: 2548 | H3: 8106
A4: 5 | B4: 40228 | C4: Leather messenger bag | D4: 1611968.2 | E4: 102776 | F4: 39.93 | G4: 2514 | H4: 8106
A5: 2 | B5: 40235 | C5: Organic coconut oil | D5: 1409727.6 | E5: 75352 | F5: 46.63 | G5: 2561 | H5: 8106
A6: 3 | B6: 40242 | C6: Bluetooth wireless earbuds | D6: 1554806.7 | E6: 50703 | F6: 46.5 | G6: 2625 | H6: 8106
A7: 2 | B7: 40249 | C7: Floral patterned throw pillow | D7: 1439541.6 | E7: 68255 | F7: 57.79 | G7: 2667 | H7: 8106
A8: 1 | B8: 40256 | C8: Bamboo cutting board set | D8: 1472515.8 | E8: 94790 | F8: 54.58 | G8: 2720 | H8: 8106
A9: 4 | B9: 40263 | C9: Aromatherapy essential oil diffuser | D9: 1404429.9 | E9: 120506 | F9: 51.45 | G9: 2732 | H9: 8106
A10: 5 | B10: 40270 | C10: Resistance band set | D10: 1594968.3 | E10: 65593 | F10: 62.27 | G10: 2719 | H10: 7808
A11: 2 | B11: 40277 | C11: Ceramic plant pot with saucer | D11: 1545418.5 | E11: 21998 | F11: 65.86 | G11: 2770 | H11: 7808
A12: 3 | B12: 40284 | C12: Insulated lunch box | D12: 1466058.3 | E12: 126668 | F12: 66.32 | G12: 2808 | H12: 7808
A13: 1 | B13: 40291 | C13: Himalayan salt lamp | D13: 1391256.1 | E13: 110653 | F13: 64.84 | G13: 2795 | H13: 7808
... A500: 4 | B500: 40697 | C500: Vegan leather wallet | D500: 2065377.1 | E500: 138575 | F500: 78.26 | G500: 3683 | H500: 5946

Sheet INTRODUCTION

Sheet Dashboard

Sheet New forecast model 
A1: Sales forecast model (All values are in currency units) | W1: Product | X1: Q1 Forecast | Y1: Q2 Forecast | Z1: Q3 Forecast | AA1: Q4 Forecast
W2: Stainless steel french press coffee maker | X2: 4309189 | Y2: 1100505 | Z2: 2749890 | AA2: 3125314
W3: Yoga mat with carrying strap | X3: 4110849 | Y3: 1824529 | Z3: 3681782 | AA3: 3941943
W4: Ceramic plant pot with saucer | X4: 4086653 | Y4: 2489968 | Z4: 1222596 | AA4: 1454250
W5: Glass meal prep containers set | X5: 3856518 | Y5: 902774 | Z5: 2921821 | AA5: 1248245
W6: Vegan leather wallet | X6: 3854920 | Y6: 138434 | Z6: 2758943 | AA6: 1351325
W7: Resistance band set | X7: 3550235 | Y7: 1731255 | Z7: 909012 | AA7: 0
W8: Memory foam travel neck pillow | X8: 3065826 | Y8: 1584650 | Z8: 3661923 | AA8: 3940828
W9: Aromatherapy essential oil diffuser | X9: 2647991 | Y9: 1503445 | Z9: 668847 | AA9: 482579
W10: LED desk lamp with USB charging port | X10: 2639788 | Y10: 2585342 | Z10: 978929 | AA10: 1138334
W11: Insulated lunch box | X11: 2431235 | Y11: 2082238 | Z11: 0 | AA11: 2557823
W12: Bamboo cutting board set | X12: 2234571 | Y12: 1378862 | Z12: 995835 | AA12: 0
W13: Handwoven rattan basket | X13: 2214434 | Y13: 1810605 | Z13: 2577027 | AA13: 3873261
... W21: Leather messenger bag | X21: 563464 | Y21: 3219492 | Z21: 2140992 | AA21: 2942338

Sheet Inventory model
A1: Inventory Planning Metrics (All values are in currency units)
A2: Product | B2: EOQ | C2: Safety Stock | D2: Reorder Point | E2: Avg Daily Demand | F2: Std Daily Demand | G2: Unit Cost (Estimated) | H2: Holding Cost
A3: Blueberry scented candle | B3: 19674.97 | C3: 563453.17 | D3: 3306841.7 | E3: 195956.32 | F3: 91551.73 | G3: 184.77 | H3: 36.95
A4: Stainless steel water bottle | B4: 19673.86 | C4: 642906.17 | D4: 3478633.8 | E4: 202551.97 | F4: 104461.51 | G4: 191.01 | H4: 38.2
A5: Leather messenger bag | B5: 19652.91 | C5: 585843.34 | D5: 3383099.2 | E5: 199803.99 | F5: 95189.76 | G5: 188.82 | H5: 37.76
A6: Organic coconut oil | B6: 19707.22 | C6: 579244.71 | D6: 3347960.1 | E6: 197765.38 | F6: 94117.59 | G6: 185.86 | H6: 37.17
A7: Bluetooth wireless earbuds | B7: 19701.88 | C7: 574771.1 | D7: 3361817 | E7: 199074.71 | F7: 93390.7 | G7: 187.19 | H7: 37.44
A8: Floral patterned throw pillow | B8: 19685.99 | C8: 614538.3 | D8: 3461726.8 | E8: 203370.61 | F8: 99852.21 | G8: 191.54 | H8: 38.31
A9: Bamboo cutting board set | B9: 19718.91 | C9: 618206.66 | D9: 3345664.9 | E9: 194818.45 | F9: 100448.26 | G9: 182.88 | H9: 36.58
A10: Aromatherapy essential oil diffuser | B10: 19713.99 | C10: 601479.65 | D10: 3232406.8 | E10: 187923.37 | F10: 97730.4 | G10: 176.49 | H10: 35.3
A11: Resistance band set | B11: 19693.14 | C11: 618031.32 | D11: 3320215.8 | E11: 193013.18 | F11: 100419.77 | G11: 181.66 | H11: 36.33
A12: Ceramic plant pot with saucer | B12: 19782.91 | C12: 684575.88 | D12: 3598004.3 | E12: 208102.03 | F12: 111232.15 | G12: 194.08 | H12: 38.82
A13: Insulated lunch box | B13: 19733.56 | C13: 570460.65 | D13: 3318939.8 | E13: 196319.94 | F13: 92690.33 | G13: 184.01 | H13: 36.8
A14: Himalayan salt lamp | B14: 19719.87 | C14: 607764 | D14: 3421191.1 | E14: 200959.08 | F14: 98751.5 | G14: 188.62 | H14: 37.72
... A22: LED desk lamp with USB charging port | B22: 19657.18 | C22: 573512.64 | D22: 3304717.5 | E22: 195086.06 | F22: 93186.23 | G22: 184.28 | H22: 36.86

Sheet Promotion Strategy
A8: TOP 3 HIGHEST SALES FORECAST PRODUCT FOR NEXT 4 QUARTERS
A9: Quarter | B9: Rank | C9: Product | D9: Sales Forecast
A10: Q1 | B10: 1 | C10: =INDEX('New forecast model '!$W$2:$W$21, MATCH(LARGE('New forecast model '!$X$2:$X$21, ROWS('New forecast model '!$W$2:W2)), 'New forecast model '!$X$2:$X$21, 0)) -> Stainless steel french press coffee maker | D10: =LARGE('New forecast model '!$X$2:$X$21, ROWS('New forecast model '!$W$2:W2)) -> 4309189
A11: Q1 | B11: 2 | C11: =INDEX('New forecast model '!$W$2:$W$21, MATCH(LARGE('New forecast model '!$X$2:$X$21, ROWS('New forecast model '!$W$2:W3)), 'New forecast model '!$X$2:$X$21, 0)) -> Yoga mat with carrying strap | D11: =LARGE('New forecast model '!$X$2:$X$21, ROWS('New forecast model '!$W$2:W3)) -> 4110849
A12: Q1 | B12: 3 | C12: =INDEX('New forecast model '!$W$2:$W$21, MATCH(LARGE('New forecast model '!$X$2:$X$21, ROWS('New forecast model '!$W$2:W4)), 'New forecast model '!$X$2:$X$21, 0)) -> Ceramic plant pot with saucer | D12: =LARGE('New forecast model '!$X$2:$X$21, ROWS('New forecast model '!$W$2:W4)) -> 4086653
A13: Q2 | B13: 1 | C13: =INDEX('New forecast model '!$W$2:$W$21, MATCH(LARGE('New forecast model '!$Y$2:$Y$21, ROWS('New forecast model '!$W$2:W2)), 'New forecast model '!$Y$2:$Y$21, 0)) -> Blueberry scented candle | D13: =LARGE('New forecast model '!$Y$2:$Y$21, ROWS('New forecast model '!$W$2:W2)) -> 3749562
A14: Q2 | B14: 2 | C14: =INDEX('New forecast model '!$W$2:$W$21, MATCH(LARGE('New forecast model '!$Y$2:$Y$21, ROWS('New forecast model '!$W$2:W3)), 'New forecast model '!$Y$2:$Y$21, 0)) -> Leather messenger bag | D14: =LARGE('New forecast model '!$Y$2:$Y$21, ROWS('New forecast model '!$W$2:W3)) -> 3219492
A15: Q2 | B15: 3 | C15: =INDEX('New forecast model '!$W$2:$W$21, MATCH(LARGE('New forecast model '!$Y$2:$Y$21, ROWS('New forecast model '!$W$2:W4)), 'New forecast model '!$Y$2:$Y$21, 0)) -> Stainless steel water bottle | D15: =LARGE('New forecast model '!$Y$2:$Y$21, ROWS('New forecast model '!$W$2:W4)) -> 3206482
A16: Q3 | B16: 1 | C16: =INDEX('New forecast model '!$W$2:$W$21, MATCH(LARGE('New forecast model '!$Z$2:$Z$21, ROWS('New forecast model '!$W$2:W2)), 'New forecast model '!$Z$2:$Z$21, 0)) -> Yoga mat with carrying strap | D16: =LARGE('New forecast model '!$Z$2:$Z$21, ROWS('New forecast model '!$W$2:W2)) -> 3681782
A17: Q3 | B17: 2 | C17: =INDEX('New forecast model '!$W$2:$W$21, MATCH(LARGE('New forecast model '!$Z$2:$Z$21, ROWS('New forecast model '!$W$2:W3)), 'New forecast model '!$Z$2:$Z$21, 0)) -> Memory foam travel neck pillow | D17: =LARGE('New forecast model '!$Z$2:$Z$21, ROWS('New forecast model '!$W$2:W3)) -> 3661923
A18: Q3 | B18: 3 | C18: =INDEX('New forecast model '!$W$2:$W$21, MATCH(LARGE('New forecast model '!$Z$2:$Z$21, ROWS('New forecast model '!$W$2:W4)), 'New forecast model '!$Z$2:$Z$21, 0)) -> Glass meal prep containers set | D18: =LARGE('New forecast model '!$Z$2:$Z$21, ROWS('New forecast model '!$W$2:W4)) -> 2921821
A19: Q4 | B19: 1 | C19: =INDEX('New forecast model '!$W$2:$W$21, MATCH(LARGE('New forecast model '!$AA$2:$AA$21, ROWS('New forecast model '!$W$2:W2)), 'New forecast model '!$AA$2:$AA$21, 0)) -> Reusable silicone food storage bags | D19: =LARGE('New forecast model '!$AA$2:$AA$21, ROWS('New forecast model '!$W$2:W2)) -> 4759480
A20: Q4 | B20: 2 | C20: =INDEX('New forecast model '!$W$2:$W$21, MATCH(LARGE('New forecast model '!$AA$2:$AA$21, ROWS('New forecast model '!$W$2:W3)), 'New forecast model '!$AA$2:$AA$21, 0)) -> Yoga mat with carrying strap | D20: =LARGE('New forecast model '!$AA$2:$AA$21, ROWS('New forecast model '!$W$2:W3)) -> 3941943
A21: Q4 | B21: 3 | C21: =INDEX('New forecast model '!$W$2:$W$21, MATCH(LARGE('New forecast model '!$AA$2:$AA$21, ROWS('New forecast model '!$W$2:W4)), 'New forecast model '!$AA$2:$AA$21, 0)) -> Memory foam travel neck pillow | D21: =LARGE('New forecast model '!$AA$2:$AA$21, ROWS('New forecast model '!$W$2:W4)) -> 3940828

Sheet Pivot
I1: Product | J1: Aromatherapy essential oil diffuser
I2: Store | J2: 1
A3: Sum of Weekly_Sales | B3: Column Labels
A4: Row Labels | B4: 2 | C4: 1 | D4: 4 | E4: 5 | F4: 3 | G4: Grand Total | I4: Row Labels | J4: Sum of Weekly_Sales
A5: 2010 | B5: 75355023 | C5: 54862272 | D5: 53551101 | E5: 50268301 | F5: 48945889 | G5: 282982586 | I5: 2010
A6: Qtr1 | B6: 13559810 | C6: 10030626 | D6: 9268407.7 | E6: 5855327.7 | F6: 8476850.1 | G6: 47191021 | I6: Qtr1
A7: Qtr2 | B7: 20134552 | C7: 13537646 | D7: 13763179 | E7: 15563631 | F7: 11108422 | G7: 74107431 | I7: 40221 | J7: 420728.96
A8: Qtr3 | B8: 20801112 | C8: 12720308 | D8: 10925437 | E8: 13023234 | F8: 15161781 | G8: 72631872 | I8: 2011
A9: Qtr4 | B9: 20859550 | C9: 18573693 | D9: 19594077 | E9: 15826108 | F9: 14198836 | G9: 89052262 | I9: Qtr3
A10: 2011 | B10: 68845622 | C10: 43710262 | D10: 42212043 | E10: 43361883 | F10: 46719058 | G10: 2.4484887e+08 | I10: 40802 | J10: 1691439.5
A11: Qtr1 | B11: 19151978 | C11: 11445722 | D11: 11662590 | E11: 14304312 | F11: 13235693 | G11: 69800297 | I11: 2012
A12: Qtr2 | B12: 20840307 | C12: 13136500 | D12: 11372220 | E12: 9673689.2 | F12: 14056452 | G12: 69079168 | I12: Qtr1
A13: Qtr3 | B13: 12390217 | C13: 9452046.9 | D13: 11102524 | E13: 10827993 | F13: 7074161.8 | G13: 50846942 | I13: 40921 | J13: 367438.62
A14: Qtr4 | B14: 16463120 | C14: 9675993.5 | D14: 8074708.3 | E14: 8555887.8 | F14: 12352751 | G14: 55122460 | I14: Qtr3
A15: 2012 | B15: 46371674 | C15: 29738072 | D15: 31397633 | E15: 31400629 | F15: 28815185 | G15: 1.6772319e+08 | I15: 41103 | J15: 1527014
A16: Qtr1 | B16: 13780692 | C16: 10350712 | D16: 11268598 | E16: 7482584.4 | F16: 7791207.1 | G16: 50673793 | I16: Grand Total | J16: 4006621.1
A17: Qtr2 | B17: 15170532 | C17: 7982321.3 | D17: 8550287.7 | E17: 12318196 | F17: 7661343.9 | G17: 51682681
A18: Qtr3 | B18: 13634365 | C18: 8995913.9 | D18: 7582703 | E18: 7773352.2 | F18: 11868974 | G18: 49855308
A19: Qtr4 | B19: 3786084.8 | C19: 2409125.4 | D19: 3996044.2 | E19: 3826495.9 | F19: 1493659.7 | G19: 15511410
A20: Grand Total | B20: 1.9057232e+08 | C20: 1.2831061e+08 | D20: 1.2716078e+08 | E20: 1.2503081e+08 | F20: 1.2448013e+08 | G20: 6.9555465e+08
A30: Sum of Weekly_Sales | B30: Column Labels
B31: 2010 | F31: 2011 | J31: 2012 | N31: Grand Total
B32: Qtr1 | C32: Qtr2 | D32: Qtr3 | E32: Qtr4 | F32: Qtr1 | G32: Qtr2 | H32: Qtr3 | I32: Qtr4 | J32: Qtr1 | K32: Qtr2 | L32: Qtr3 | M32: Qtr4
A33: Row Labels
A34: Ceramic plant pot with saucer | B34: 4488419.6 | C34: 3392070.5 | D34: 3793781.7 | E34: 5912222.7 | F34: 1391014 | G34: 5765698 | H34: 2027741.9 | I34: 1502562.8 | J34: 4221637.7 | K34: 442074.79 | L34: 3480631.1 | N34: 36417855
A35: Insulated lunch box | B35: 4353707.2 | C35: 1466058.3 | D35: 5669966.3 | E35: 4315886 | F35: 1327405.4 | G35: 5719589 | H35: 375629.51 | I35: 3282802.5 | J35: 3964236.1 | K35: 419497.95 | L35: 3461210.9 | N35: 34355989
A36: Aromatherapy essential oil diffuser | B36: 3816172 | C36: 1870619.2 | D36: 3671107.2 | E36: 6051924.9 | F36: 2116475.4 | G36: 3557838.9 | H36: 2057807.1 | I36: 1630989.9 | J36: 3842126.4 | K36: 2320001.7 | L36: 1527014 | M36: 424513.08 | N36: 32886590
A37: Bamboo cutting board set | B37: 3799235.3 | C37: 2260637.1 | D37: 3451371.6 | E37: 6717976.6 | F37: 2039818.4 | G37: 3865671.3 | H37: 3522279.4 | J37: 3878954.3 | K37: 2376625.6 | L37: 1769854.2 | M37: 410804.39 | N37: 34093228
A38: Bluetooth wireless earbuds | B38: 3692616.2 | C38: 2258769.7 | D38: 3389005.8 | E38: 5939440 | F38: 2470204.2 | G38: 3302643.3 | H38: 3745380.9 | I38: 551221.21 | J38: 3381065.1 | K38: 3869923.5 | L38: 389813.02 | M38: 1847990.4 | N38: 34838073
A39: Floral patterned throw pillow | B39: 3563993.1 | C39: 2221610.5 | D39: 3252889.2 | E39: 6840280.9 | F39: 2484139.4 | G39: 3485859.1 | H39: 3569516.8 | I39: 410553.88 | J39: 3514246.5 | K39: 3968750.7 | M39: 2278016 | N39: 35589856
A40: Organic coconut oil | B40: 3546717 | C40: 4212493.2 | D40: 1448938.9 | E40: 5656563.5 | F40: 2721248.9 | G40: 3364991.2 | H40: 3729947.1 | I40: 510747.62 | J40: 3118845.7 | K40: 3983311.7 | L40: 414392.09 | M40: 1900745.1 | N40: 34608942
A41: Himalayan salt lamp | B41: 2434061 | C41: 3457443.8 | D41: 5631959.2 | E41: 3287628.8 | F41: 3074950.1 | G41: 5703477.3 | H41: 365248.94 | I41: 3441111.8 | J41: 3936916.2 | K41: 422965.33 | L41: 3412076.4 | N41: 35167839
A42: Resistance band set | B42: 2412126 | C42: 3524704.6 | D42: 3666540.8 | E42: 5187850.4 | F42: 3388896.6 | G42: 3670041 | H42: 2045288.5 | I42: 1493525.9 | J42: 4157562.1 | K42: 2327382.9 | L42: 1497954.8 | M42: 405432.7 | N42: 33777306
A43: Handwoven rattan basket | B43: 2331006.7 | C43: 3478913.1 | D43: 5444423.3 | E43: 2685182.6 | F43: 3400999.8 | G43: 4171923.7 | H43: 1488538.1 | I43: 3712122.4 | J43: 2395007.6 | K43: 1899676.9 | L43: 3857140.1 | N43: 34864934
A44: Reusable silicone food storage bags | B44: 2301057.4 | C44: 3379789.9 | D44: 5595282.6 | E44: 2708520.6 | F44: 3350823.2 | G44: 5979499.8 | H44: 368477.93 | I44: 3429619.1 | J44: 4062824 | L44: 3766998.4 | N44: 34942893
A45: Stainless steel french press coffee maker | B45: 1897429.4 | C45: 3617982.6 | D45: 4063676.3 | E45: 5034953.3 | F45: 3767207.6 | G45: 4187796 | H45: 1455120 | I45: 3899785.5 | J45: 2302642.9 | K45: 1521577.9 | L45: 3979211.2 | N45: 35727383
A46: Yoga mat with carrying strap | B46: 1894324.1 | C46: 3739536.8 | D46: 3987494.7 | E46: 4193386.6 | F46: 3760455.8 | G46: 4386805.3 | H46: 1534849.6 | I46: 4361311.1 | J46: 2260191.7 | K46: 1621031.7 | L46: 3881228.2 | N46: 35620616
A47: Memory foam travel neck pillow | B47: 1762539.3 | C47: 3829644.9 | D47: 4098081.9 | E47: 3254277.8 | F47: 4155181.7 | G47: 2407202.2 | H47: 3263169.8 | I47: 4091985.5 | J47: 411775.8 | K47: 3597964.3 | L47: 3814207.3 | N47: 34686031
A48: Blueberry scented candle | B48: 1643690.9 | C48: 5712287.4 | D48: 1865820.8 | E48: 3591211.2 | F48: 4126130.3 | G48: 1495064.8 | H48: 3606600.7 | I48: 2989661.7 | J48: 1550369.9 | K48: 3900191.4 | L48: 2238254.4 | M48: 1573072.8 | N48: 34292356
A49: Stainless steel water bottle | B49: 1641957.4 | C49: 4186575.2 | D49: 3392377.8 | E49: 3681646.6 | F49: 4418854.9 | G49: 1614259.4 | H49: 3714852 | I49: 3696881.1 | J49: 1459601.2 | K49: 3976820.7 | L49: 2154700.3 | M49: 1508068.8 | N49: 35446595
...
